Workbook

Sheet ALL Projects
A1: ID | B1: Name | C1: E-mail | D1: Registered Course | E1: Project Code | F1: Supervisor | G1: TA | H1: Project Title | I1: Project Summary | J1: Project Objectives | K1: External Supervisor | L1: Company | M1: Comment | N1: Choice
A2: 231000119 | B2: Mohamed Abdellatif | C2: m.abdellatif2319@nu.edu.eg | E2: ITCS-GP26-01 | F2: Prof. Noha Gamal Eldin Saad | H2: AI powered Clinical Management System | I2: Our project is an AI-powered Clinical Management System designed to streamline and modernize the daily operations of healthcare clinics. The system provides a centralized platform for managing all clinic activities, including doctors, patients, nurses, administrators, appointments, medical records, billing, and reporting. By integrating artificial intelligence, the platform reduces administrative workload, improves efficiency, enhances patient experience, and supports healthcare professionals in delivering better care.
A3: 231000010 | C3: Z.ahmed2310@nu.edu.eg
A4: 231000573 | C4: O.Amin2373@nu.edu.eg
A5: 231000765 | C5: M.Mohamed2365@nu.edu.eg
A10: 231000402 | B10: Ahmed Afifi | C10: A.Mohamed2302@nu.edu.eg | E10: ITCS-GP26-02 | F10: Prof. Sahar Selim Soussa | H10: AgentOS: A Native Operating Environment for Software Engineering Agents | I10: Recent advances in AI agents have enabled systems capable of performing complex tasks such as software development, research assistance, and workflow automation. However, most existing agents operate as standalone applications that depend on the user's active device and continuous supervision. This project proposes AgentOS, a native operating environment designed to host and manage persistent autonomous AI agents. The platform will support continuous agent execution, task persistence, remote monitoring, and notification-based communication, allowing agents to operate independently while keeping users informed and involved when necessary. The system aims to provide a foundation for future agent-centric computing environments that support long-running AI workflows and multi-agent collaboration.
A11: 231001706 | C11: P.Mohamed2306@nu.edu.eg
A12: 231001462 | C12: Y.Essam2362@nu.edu.eg
A13: 231000713 | C13: A.Khaled2313@nu.edu.eg
A14: 231000057 | C14: Z.Hatem2357@nu.edu.eg
A18: 231000616 | B18: Mahmoud Khaled | C18: M.Khaled2316@nu.edu.eg | E18: ITCS-GP26-03 | F18: Prof. Salem Farag Hegazy + Alaa Fathy Sheta | H18: Historical Photo Geolocalization: Estimating GPS Coordinates Using Computer Vision and GIS | I18: This graduate project, Historical Photo Geolocalization, utilizes computer vision and geographic information systems (GIS) to estimate precise GPS coordinates for undated, degraded historical photographs that completely lack metadata. Unlike existing modern AI models that merely classify general scenes (like cities or countries) using modern training data, this system uses a custom pipeline to extract visual features from scratched, sepia, or low-resolution historic images. By identifying enduring landmarks and applying camera geometry, the system geometrically triangulates the photographer's exact vantage point to a sub-10-meter precision. Each estimated coordinate is saved to a "Historical Viewpoints Database" along with an estimated compass direction and a confidence radius, effectively creating an interactive, searchable 3D map that allows modern researchers to stand in the exact footsteps of history.
A19: 231000621 | C19: z.khaled2321@nu.edu.eg
A20: 231000144 | C20: o.khaled2344@nu.edu.eg
A21: 231000562 | C21: y.mohamed2362@nu.edu.eg
A22: 231000546 | C22: m.mohamedshalaby2346@nu.edu.eg
A26: 231001369 | B26: Salma Zakaria | C26: s.ali2369@nu.edu.eg | E26: ITCS-GP26-04 | F26: Prof. Ahmed Fathy El Nokrashy | H26: Intelligent Smart home loT system | I26: Our application is designed to help caregivers and families provide better care for patients, elderly individuals, and children. The app sends timely medication reminders to ensure that doses are never missed. It also includes a location-monitoring feature that alerts caregivers if the patient or child moves outside a designated safe area, we will also add some other critical features later to making it a comprehensive solution for safety, health management, and caregiving support.
A27: 231000646 | C27: B.ali2346@nu.edu.eg
A28: 231000679 | C28: o.abdelwahed2379@nu.edu.eg
A29: 231001588 | C29: M.atef2388@nu.edu.eg
A34: 221000499 | B34: Mohamed wael | C34: M.Wael2299@nu.edu.eg | E34: ITCS-GP26-05 | F34: Prof. Islam Tharwat Abdelhalim | H34: Gamified Cybersecurity Awareness Platform | I34: Gamified Cybersecurity Awareness Platform Most cybersecurity breaches happen due to human error rather than technical failure, yet traditional security training is often ignored or forgotten. This project is an interactive, game-based learning platform that teaches users practical cybersecurity skills and awareness through engaging challenges, simulations, and progress tracking. Key features: Interactive lessons covering core topics: phishing, password security, social engineering, malware, and safe browsing habits Simulated real-world scenarios (e.g., spotting phishing emails or suspicious links) with instant feedback Points, levels, badges, and leaderboards to drive engagement Hands-on exercises that build practical security habits Individual progress tracking and performance reports Admin dashboard for instructors or organizations to monitor group progress and identify weak areas
A35: 221002127 | C35: M.magdy2227@nu.edu.eg
A36: 231001639 | C36: M.MAHMOUD2339@nu.edu.eg
A37: 231001650 | C37: S.reda2350@nu.edu.eg | G37: Smart Rehabilitation Assistant with Vision-Based Feedback
A38: 231000818 | C38: r.Ramadan2318@nu.edu.eg
A39: 221001245 | C39: m.khaled2245@nu.edu.eg
A42: 231000547 | B42: Zyad Mohamed Saied | C42: Z.Mohamed2347@nu.edu.eg | E42: ITCS-GP26-06 | F42: Prof. Ahmed Fathy El Nokrashy | H42: Smart Campus | I42: The graduation project integrates smart campus features—including an AI chatbot, smart classrooms, study spaces, transportation, parking, and exam scheduling—while leveraging the team’s expertise in Generative AI, Fullstack Development, Data, Computer Vision/IoT, and DevOps to deliver an intelligent and practical campus solution.
A43: 231002012 | C43: R.Hatem2312@nu.edu.eg
A44: 231002060 | C44: M.Hatem2360@nu.edu.eg
A45: 231000674 | C45: O.Salama2374@nu.edu.eg
A46: 231000857 | C46: N.Diaa2357@nu.edu.eg
A47: 231001228 | C47: S.Hosaam2328@nu.edu.eg
A50: 231001880 | B50: Hamza Taher Essam Ibrahim | C50: h.taher2380@nu.edu.eg | E50: ITCS-GP26-07 | F50: Prof. Amira Tarek Mahmoud | H50: AI-Powered Source Code Cleaner, Optimizer & Testing System | I50: This project proposes an AI-powered platform that automatically analyzes source code and improves it through intelligent code cleanup, performance optimization, and automated test generation, all within a unified system.
A51: 231001297 | C51: Y.ASHRAF2397@nu.edu.eg
A52: 231000967 | C52: O.Magdy2367@nu.edu.eg
A53: 231002205 | C53: Z.nabil2305@nu.edu.eg
A54: 231000179 | C54: y.amr2379@nu.edu.eg
A58: 231001417 | B58: Sara Mohamed Lotfy | C58: S.Mohamed2317@nu.edu.eg | E58: ITCS-GP26-08 | F58: Prof. Mai Mohamed Said | H58: AI-RadConnect: An Intelligent Teleradiology Platform for Real-Time Radiological Interpretation, Clinical Decision Support, and Automated Report Generation Using Multimodal Artificial Intelligence | I58: AI-RadConnect is a graduation project that aims to develop an intelligent teleradiology platform that uses artificial intelligence to support radiologists in interpreting medical images and making faster clinical decisions. The system will analyze medical images, prioritize urgent cases, generate preliminary radiology reports, and provide explainable AI-based diagnostic support. The platform will integrate medical imaging with relevant clinical information using deep learning and multimodal AI techniques to improve diagnostic accuracy and reduce reporting time. It will also include automated report generation and case prioritization to enhance workflow efficiency. The project will be developed and evaluated using publicly available medical imaging datasets, demonstrating the potential of AI to improve the quality and accessibility of radiology services.
A59: 231000980 | C59: M.mohamed2380@nu.edu.eg
A60: 231001409 | C60: A.Tamer2309@nu.edu.eg
A61: 231000568 | C61: A.Mohamed2368@nu.edu.eg
...

Sheet Sheet1
A1: ID | B1: Start time | C1: Completion time | D1: Email | E1: Name | F1: Last modified time | G1: Your Name | H1: Your E-mail | I1: Title of Proposed Topic. | J1: To which research group does this topic belong? | K1: Summary of Proposed Topic | L1: Objective of Proposed Topic | M1: Is this topic related to a specific team? | N1: If Yes, Please provide the Team Leader's ID
A2: 9 | B2: 45789.527 | C2: 45789.536 | D2: anonymous | G2: Ahmed El-Mahdy | H2: aelmahdy@nu.edu.eg | I2: Quantum Drug Discovery | J2: Quantum Computing | K2: Quantum computing is the best way to simulate the complex behaviour of molecules than classical computers because quantum computing itself follows the same behaviour of the molecules! Drug design relies heavily on finding the optimal configuration of electrons on a drug molecule; this, in turn, tells us about how good, or effective, the drug is. | L2: This project aims to develop software for non-quantum specialists to assist in using quantum computers to aid in drug design. | M2: Yes | N2: Two teams have contacted me, but don't know their IDs
A3: 37 | B3: 45811.456 | C3: 45811.493 | D3: anonymous | G3: Ghada Khoriba | H3: ghadakhoriba@nu.edu.eg | I3: Deep Learning–Driven Feedback System for MMA Athlete Monitoring | J3: Ubiquitous and Visual Computing | K3: This project proposes a deep learning–driven feedback system designed to monitor and enhance Mixed Martial Arts (MMA) athlete performance and safety. By combining wearable sensor data with real-time video analysis, the system leverages multimodal data fusion to detect and interpret complex MMA movements such as strikes, blocks, and evasions. Advanced pose estimation and action recognition models will provide automated, objective assessments of technique quality, fatigue levels, and injury risk indicators. | L3: The system will deliver real-time feedback to coaches and athletes, enabling immediate performance corrections and long-term data-driven training strategies. The main objectives are to (1) develop accurate AI models for MMA-specific movement recognition, (2) integrate wearable and video data into a seamless monitoring pipeline, and (3) Validate the system with elite fighters in live training scenarios. | M3: Yes | N3: 221000147
A4: 39 | B4: 45812.62 | C4: 45812.622 | D4: anonymous | G4: Mustafa Elattar | H4: melattar@nu.edu.eg | I4: A Psychologically-Informed Task-Based Model for Facilitating Comfort Zone Expansion and Interpersonal Growth | J4: Medical Informatics | M4: Yes | N4: Jana Ayman 221000410
A5: 40 | B5: 45812.622 | C5: 45812.623 | D5: anonymous | G5: Mustafa Elattar | H5: melattar@nu.edu.eg | I5: Machine Human Integration | J5: Medical Imaging and Image Processing | M5: Yes | N5: ⁠Ahmed Kamal 221001524
A6: 41 | B6: 45813.465 | C6: 45813.467 | D6: anonymous | G6: Noha Gamal Eldin Saad Ali | H6: ngamal@nu.edu.eg | I6: NeuroQuest: AI-Powered VR Learning System for Children with Learning Difficulties | J6: Ubiquitous and Visual Computing | K6: AI-Powered Accessible Educational Game For People With Disorders And Disabilities. | M6: Yes | N6: Mohamed Mohamed Nasr, 221000089, m.mohamed2289@nu.edu.eg
A7: 42 | B7: 45813.468 | C7: 45813.469 | D7: anonymous | G7: Noha Gamal Eldin Saad Ali | H7: ngamal@nu.edu.eg | I7: Smart Rehabilitation Assistant with Vision-Based Feedback | J7: Medical Imaging and Image Processing | K7: Smart Rehabilitation Assistant with Vision-Based Feedback | M7: Yes | N7: FARAH AHMED ABDELBARI, 221001269, f.ahmed2269@nu.edu.eg
A8: 43 | B8: 45813.469 | C8: 45813.472 | D8: anonymous | G8: Noha Gamal Eldin Saad Ali | H8: ngamal@nu.edu.eg | I8: SpeakX: AI-driven platform for assessing and improving English speaking skills for Egyptians | J8: Natural language processing | K8: SpeakX is an AI-driven platform designed to improve and assess English speaking skills for Egyptians, particularly those targeting industries like call centers and tourism. Through a smart website and mobile app, SpeakX employs a virtual interviewer powered by speech recognition and natural language processing (NLP) to ask real-life questions, evaluate responses, and provide personalized feedback on grammar, fluency, vocabulary, pronunciation, sentiment, and body language. Tailored to recognize the Egyptian English accent, the system ensures fair and accurate scoring based on international standards, adapting question difficulty to user performance. It also identifies communication and confidence gaps, recommending personalized activities like pronunciation drills and confidence workshops. SpeakX supports certifications and corporate recruitment pipelines, empowering individuals and streamlining hiring for companies. A research paper will document the technical approach, challenges in accent detection and fair scoring, and improvements over traditional language learning methods. Revenue streams include subscriptions, certifications, corporate training, and advertising. | M8: Yes | N8: Abdullah Yasser Ismail, 221001008, a.yasser2208@nu.edu.eg
A9: 44 | B9: 45813.472 | C9: 45813.473 | D9: anonymous | G9: Noha Gamal Eldin Saad Ali | H9: ngamal@nu.edu.eg | I9: Portable 3D Scanner for Real World Objects) | J9: Ubiquitous and Visual Computing | K9: Portable 3D Scanner for Real World Objects) This project is about creating a small, portable 3D scanner that can scan real objects and turn them into 3D models on a computer. The scanner will use cameras and sensors to capture the shape and details of objects. It will also use AI software to make the 3D models look better and more accurate. The goal is to make a low-cost, easy-to-use device that can work anywhere, even without the internet. | M9: Yes | N9: Mohammed Ahmed Elmorsy, 221001919, m.elmorsy2219@nu.edu.eg
A10: 45 | B10: 45813.474 | C10: 45813.476 | D10: anonymous | G10: Noha Gamal Eldin Saad Ali | H10: Ngamal@nu.edu.eg | I10: AI-Powered End-to-End, Two sided Dental Assistant | J10: Medical Informatics | M10: Yes | N10: Hana Mahmoud Elashry, 221001128, h.mahmoud2228@nu.edu.eg
A11: 46 | B11: 45813.476 | C11: 45813.478 | D11: anonymous | G11: Noha Gamal Eldin Saad Ali | H11: Ngamal@nu.edu.eg | I11: I-hire.io Gen2: Full Hiring Pipeline | J11: Natural language processing | M11: Yes | N11: Abdallah Eissa Abdelhares, 231001561, a.eissa2361@nu.edu.eg
A12: 47 | B12: 45813.479 | C12: 45813.481 | D12: anonymous | G12: Noha Gamal Eldin Saad Ali | H12: ngamal@nu.edu.eg | I12: Customizing learning experience for students with different needs using AI generated content and feedback using vital sensors and emotion detection | J12: Ubiquitous and Visual Computing | M12: Yes | N12: Hana Hatem Elgabry, 221000062, h.hatem2262@nu.edu.eg
A13: 48 | B13: 45813.485 | C13: 45813.488 | D13: anonymous | G13: Noha Gamal Eldin Saad Ali | H13: ngamal@nu.edu.eg | I13: Nafaa{نفع}: is a smart charity platform that brings together trusted organizations, donors, and families in need — all in one place | J13: Software and Systems | K13: A charity App & website that will collect charity organizations together into one platform. It will target the following users: - Donors looking to donate to trusted and reputable charities - Families in need of financial, social or medical aid - Partner charities looking to broaden their reach The app will use AI features such as OCR and Multimodal to help streamline applications. | M13: Yes | N13: Farida Ashraf Hanafy, 221000407, f.ashraf2207@nu.edu.eg
A14: 49 | B14: 45811.493 | C14: 45814.001 | D14: anonymous | G14: Ghada Khoriba | H14: ghadakhoriba@nu.edu.eg | I14: Motion Capture-Free Human Motion Synthesis | J14: Ubiquitous and Visual Computing | K14: multimodal large language models and neural control rigs to generate human motion data without traditional motion capture systems | L14: Representation and Fusion of Multimodal Information: Generating high-quality 3D digital human motion faces challenges such as jitter, penetration, and foot sliding. Solutions include using parametrized human models and advanced motion generation techniques like generative adversarial networks (GANs), autoencoders, and diffusion models | M14: Yes | N14: 221000770
A15: 50 | B15: 45814.146 | C15: 45814.15 | D15: anonymous | G15: Ensaf Hussein Mohamed | H15: enmohamed@nu.edu.eg | I15: Smart Dashboard Generation for Business Analytics Using LLMs | J15: Natural language processing | K15: This project uses large language models (LLMs) to automatically generate visual dashboards from business data. Users can input queries in natural language to receive insights and analytics without coding. The system enhances business decision-making by combining NLP with smart data visualization. | M15: Yes | N15: Mohamed Waleed Eltwapty 221001161
A16: 51 | B16: 45814.15 | C16: 45814.155 | D16: anonymous | G16: Ensaf Hussein Mohamed | H16: Ensaf Hussein Mohamed | I16: Smart Dermatological Diagnosis and Skincare Guidance Using Multi-Modal LLMs | J16: Medical Imaging and Image Processing | K16: This project aims to develop a smart system that uses multi-modal large language models (LLMs) to analyze skin images and user input for accurate dermatological diagnosis. It provides personalized skincare routine recommendations based on the diagnosis and user profile. The system combines visual understanding with natural language processing to support both medical and cosmetic skin care. | M16: Yes | N16: Eman Khalid Elkalawy 221001658
A17: 52 | B17: 45815.941 | C17: 45815.945 | D17: anonymous | G17: Mai Mabrouk | H17: masaid@nu.edu.eg | I17: Artificial intelligence guided system for mRNA Vaccine components from antigen selection to delivery systems | J17: Bioinformatics | K17: The project aims to develop an integrated artificial intelligence (AI)-driven system that streamlines the design and development of mRNA vaccines by guiding key decisions from antigen selection to delivery system optimization. With the rapid advancement of mRNA vaccine technology, there is a growing need for robust computational tools that can enhance the speed, accuracy, and efficacy of vaccine development. This system will employ advanced machine learning and bioinformatics techniques to identify optimal antigens based on pathogen genomic data, predict mRNA structural stability and translation efficiency, and recommend suitable lipid nanoparticle (LNP) formulations or alternative delivery platforms. The project seeks to significantly reduce the time and cost involved in vaccine development while ensuring high immunogenicity and safety. This approach could be pivotal in responding to emerging infectious diseases and enhancing global pandemic preparedness. | L17: -Develop AI algorithms for the identification and prioritization of immunogenic antigens from pathogen genomic and proteomic data. - Predict and optimize mRNA sequence features (e.g., codon usage, GC content, secondary structures) for enhanced stability, translational efficiency, and immune response. - Design machine learning models to evaluate and select appropriate delivery systems (e.g., lipid nanoparticles) based on payload characteristics and target tissue. -Integrate all modules into a user-friendly, end-to-end computational platform for guiding mRNA vaccine development. | M17: Yes | N17: Mohamed Emad - 221001465
A18: 53 | B18: 45815.946 | C18: 45815.949 | D18: anonymous | G18: Mai Mabrouk | H18: masaid@nu.edu.eg | I18: MediVault: A Smart Mobile Application for Comprehensive Patient Medical History Management | J18: Medical Informatics | K18: In today's healthcare landscape, patients often receive medical care from multiple providers, leading to fragmented and inconsistent records. This disconnection can result in delays, redundant testing, misdiagnoses, and poor health outcomes. There is a critical need for a centralized, secure, and intelligent platform that enables patients and healthcare providers to access and manage complete medical history data in a user-friendly format. Patients lack a centralized digital platform where their entire medical history—ranging from diagnoses and prescriptions to radiology images and lifestyle data—is securely stored and easily accessible. This fragmentation can lead to: - Inaccurate or incomplete diagnoses - Repeated lab/imaging tests - Medication errors - Difficulty in coordinating care between specialists - Ineffective chronic disease management | L18: - Design and develop a mobile application that serves as a secure, smart medical history vault for patients. - Ensure interoperability with existing healthcare systems (EHRs) using FHIR standards. - Enable AI-powered summarization of medical history for quick review by clinicians. - Provide data visualization tools and alerts for both patients and caregivers. - Incorporate advanced privacy and access control features, including emergency access modes. | M18: Yes | N18: Mohamed Gamal Elmorsy ID: 221002212
A19: 54 | B19: 45818.019 | C19: 45818.021 | D19: anonymous | G19: Walid Al-Atabany | H19: w.al-atabany@nu.edu.eg | I19: AI-Guided Ultrasound System for Real-Time Scanning Optimization and Skill Transfer with Expert Motion Replication | J19: Medical Imaging and Image Processing | K19: Ultrasound imaging remains a highly operator-dependent modality, where diagnostic accuracy hinges on precise probe manipulation and anatomical view acquisition. To address this challenge, we propose a dual-function AI-guided ultrasound system that both assists in real-time scanning and supports training through expert motion modeling. The system employs inertial measurement units (IMUs), optical tracking, and synchronized ultrasound video to capture and learn expert probe trajectories during high-quality scans. These motion profiles—linked to specific anatomical targets—are used to build a predictive model of optimal probe movement and image quality. During live scanning, the system classifies the current view using deep learning models (e.g., CNNs or vision transformers), evaluates image quality, and provides intelligent feedback on probe adjustments (e.g., tilt, rotation, translation) to help operators achieve diagnostically complete views. For novice users, the system offers a training mode that compares their probe manipulation to expert benchmarks in real-time, delivering corrective guidance through visual, haptic, or auditory cues. This AI-powered assistant not only reduces intra- and inter-operator variability in clinical workflows but also accelerates skill acquisition by transforming expert motion into an interactive, feedback-driven learning experience. Ultimately, the system aims to standardize ultrasound acquisition quality, improve diagnostic confidence, and extend imaging capability to non-expert radiologists in both clinical and educational settings. | M19: Yes | N19: Ahmed Bahaaeldin Abdou | ID: 221001120
A20: 55 | B20: 45818.533 | C20: 45818.534 | D20: anonymous | G20: Islam Tharwat | H20: ihalim@nu.edu.eg | I20: Interactive Platform for Simulating Cybersecurity Writeups Using AI | J20: Cybersecurity and Digital Forensics | K20: A web-based platform designed for ethical hackers and cybersecurity students, where users can upload or explore writeups (technical reports) of real-world vulnerabilities. The platform uses AI to analyze the writeup and automatically generate a working simulation environment where users can practically execute and test the vulnerability step-by-step. | M20: Yes | N20: Hana Hafez 211000912 Alaa sari Erfan 221001779 Malak Hassan 221000447 Omar Mohamed221001706 222000071 Mostafa elgendy 221001706
A21: 56 | B21: 45818.83 | C21: 45818.832 | D21: anonymous | G21: Sahar Selim | H21: sselim@nu.edu.eg | I21: AI-Powered Medical Imaging for Disease Diagnosis and Segmentation | J21: Medical Imaging and Image Processing | M21: Yes | N21: 221001609
A22: 57 | B22: 45825.509 | C22: 45825.51 | D22: anonymous | G22: Noha Gamal El-Din Saad Ali + Mustafa El-Attar | H22: ngamal@nu.edu.eg | I22: Vigil: AI-Powered Smart Surveillance with Real-Time Scene Understanding and Anomaly Detection | J22: Ubiquitous and Visual Computing | M22: Yes | N22: Abdala Alaa Atia – CS Department – GPA: 2.95, Email: a.alaa2236@nu.edu.eg | ID: 221001636
A23: 58 | B23: 45825.587 | C23: 45825.591 | D23: anonymous | G23: Noha Gamal El-Din Saad Ali | H23: ngamal@nu.edu.eg | I23: AI-Powered Application | J23: Software and Systems | M23: Yes | N23: Name: Mahmoud Khalaf Mohammed ID: 221001989 GPA: 3.92 Major: CS - Big Data Email: m.khalaf2289@nu.edu.eg
A24: 59 | B24: 45826.509 | C24: 45826.511 | D24: anonymous | G24: Noha Gamal El-Din Saad Ali | H24: ngamal@nu.edu.eg | I24: Computer ecosystem AI Assistant | J24: Software and Systems | M24: Yes | N24: Zaynab Essam Abdullah ID: 221001623 Phone: 01024690537 GPA: 3.92 Major: Computer Science (Big Data)
A25: 60 | B25: 45831.946 | C25: 45831.947 | D25: anonymous | G25: Sahar Selim | H25: sselim@nu.edu.eg | I25: A Lightweight, Privacy-Preserving System for Detecting Deepfake Videos Using Metadata | J25: Other | M25: Yes | N25: 221000716
A26: 61 | B26: 45832.509 | C26: 45832.51 | D26: anonymous | G26: Mustafa Elattar | H26: melattar@nu.edu.eg | I26: Digital Sports Coach | J26: Ubiquitous and Visual Computing | M26: Yes | N26: 221001139
A27: 62 | B27: 45837.583 | C27: 45837.584 | D27: anonymous | G27: Islam Tharwat Abdel Halim | H27: ihalim@nu.edu.eg | I27: ClarityAI | J27: Software and Systems | K27: ClarityAI is an AI-powered platform that helps users turn raw data into meaningful insights and key performance indicators (KPIs). By simply uploading a dataset or answering a guided questionnaire, individuals and businesses can instantly generate tailored metrics, performance summaries, and strategic recommendations — without the need for technical expertise. | L27: The system uses machine learning and data analysis techniques to detect patterns, trends, and anomalies, then presents the results through clean visuals and smart insights. Whether it’s for sales, marketing, education, operations, or personal use, ClarityAI makes data-driven decision-making accessible to everyone. | M27: Yes | N27: Adham Ahmad Osama – 221001652 Ali Elsaeed – 221000508 Mariam Alaa – 221000919 Shahd Mansour – 221000293
A28: 63 | B28: 45837.584 | C28: 45837.587 | D28: anonymous | G28: Islam Tharwat Abdel Halim | H28: ihalim@nu.edu.eg | I28: AI in Cybersecurity Comp I | J28: Cybersecurity and Digital Forensics | M28: Yes | N28: Alhussein Nagdy 221002149 AbdelRahman Rahal 221001443 Mahmoud abdelgelil. 221001313 Nour Elsharkawy 221001458
A29: 64 | B29: 45837.587 | C29: 45837.587 | D29: anonymous | G29: Islam Tharwat Abdel Halim | H29: ihalim@nu.edu.eg | I29: AI in Cybersecurity Comp II | J29: Cybersecurity and Digital Forensics | M29: Yes | N29: Abdelrahman AlSammany 221000915 Youssef Fathy 221000056 Mohamed Magdy 221001891

Sheet Sheet2
A1: ID | B1: Start time | C1: Completion time | D1: Email | E1: Name | F1: Last modified time | G1: Your Name | H1: Your E-mail | I1: Title of Proposed Topic. | J1: To which research group does this topic belong? | K1: Summary of Proposed Topic | L1: Objective of Proposed Topic | M1: Is this topic related to a specific team? | N1: If Yes, Please provide the Team Leader's ID
A2: 7 | B2: 45783.96 | C2: 45783.964 | D2: anonymous | G2: Walid Al-Atabany | H2: w.al-atabany@nu.edu.eg | I2: WeddWish: A Collaborative Gifting Platform for Wedding Essentials | J2: Software and Systems | K2: This project proposes the design and development of WeddWish, a web and mobile application that enables friends, colleagues, and family members to contribute financially toward a curated wishlist of items—such as furniture, electronics, or household appliances—for individuals preparing for marriage. The platform aims to streamline the traditional gift-giving process by allowing users to create personalized wishlists, set funding goals for each item, and securely collect donations from their social network. Donors can contribute to specific items or make general donations, while recipients can track progress in real time. Key features include user authentication, wishlist customization, secure payment integration, notification systems, and administrative tools for managing contributions and purchases. The project will be developed using modern web and mobile frameworks, and will prioritize usability, accessibility, and data security. Ultimately, WeddWish seeks to foster a culture of collective support and simplify the gift-giving experience around one of life’s most important milestones. | L2: 1. To design and develop a user-friendly web and mobile platform that enables engaged individuals to create personalized wishlists and receive monetary contributions toward selected gifts. 2. To integrate secure payment processing and real-time tracking features that allow donors to contribute safely and monitor funding progress for each wishlist item. 3. To ensure accessibility, data security, and intuitive usability across devices, providing a seamless experience for both donors and recipients. | M2: No
A3: 8 | B3: 45783.98 | C3: 45783.981 | D3: anonymous | G3: Walid Al-Atabany | H3: w.al-atabany@nu.edu.eg | I3: ViScope: Visual Scene Compression for Enhanced Perception in Tunnel Vision | J3: Medical Imaging and Image Processing | K3: Peripheral vision loss, often manifesting as tunnel vision, significantly impairs spatial awareness and mobility for affected individuals. Traditional visual aids like de-magnifying optics expand the visible field but at the cost of severe image distortion and resolution loss. This project proposes the development of a novel non-linear scene compression technique tailored for patients with severe visual field restriction (e.g., ≤20°). The method aims to preserve the spatial saliency of key scene features while compressing peripheral content into the patient's residual field of view. By leveraging computer vision-based scene analysis, the system will intelligently prioritize and retarget essential visual information without inducing fisheye-like distortion. The solution will be implemented in a lab-based setting using real-time image processing tools and evaluated through simulations and user studies with low-vision emulation tools. This work has the potential to enhance situational awareness for individuals with tunnel vision, offering a meaningful step toward non-invasive, perceptually intuitive low-vision aids. | L3: 1. To design and implement a non-linear scene compression algorithm that reduces wide-field visual information into the user’s restricted central field while preserving the size and clarity of key visual features. 2. To develop a real-time computer vision system using standard visible-light cameras for dynamic scene capture and feature prioritization based on saliency and spatial relevance. 3. To evaluate the effectiveness and perceptual quality of the compression method through simulated tunnel vision experiments, focusing on target detection, scene understanding, and distortion tolerance. | M3: No
A4: 10 | B4: 45789.537 | C4: 45789.538 | D4: anonymous | G4: Ahmed El-Mahdy | H4: aelmahdy@nu.edu.eg | I4: Quantum Finance | J4: Quantum Computing | K4: Quantum finance is an emerging application in quantum computing to model how the market works. In simple terms, quantum computing can model the complex possible interactions from different stakeholders, giving better asset evaluation than classical methods. | L4: This project aims to use quantum computing for a simplified marketing problem and measures the advantage of quantum computers in comparison with current classical ones. | M4: No
A5: 11 | B5: 45789.538 | C5: 45789.539 | D5: anonymous | G5: Ahmed El-Mahdy | H5: aelmahdy@nu.edu.eg | I5: Distributed Quantum Computing | J5: Quantum Computing | K5: Distributed quantum computing is now a hot topic in quantum computing, where many quantum computers are connected together to make one large quantum system. The system relies on quantum networking to connect those computers. | L5: The project aims to develop software that automatically partitions a quantum program (circuit) into many quantum processors, making it easier for quantum software developers to test distributed algorithms. | M5: No
A6: 12 | B6: 45789.983 | C6: 45789.987 | D6: anonymous | G6: Mai Mabrouk | H6: masaid@nu.edu.eg | I6: AI-Based Early Detection of Papilledema Using Fundus Imaging | J6: Medical Informatics | K6: Papilledema, the swelling of the optic disc due to increased intracranial pressure, is a vision- and life-threatening condition that necessitates timely and accurate diagnosis. Currently, diagnosis relies on expert interpretation of fundus images, a process that is not always feasible in under-resourced or remote clinical settings. This proposal aims to develop an automated, AI-powered diagnostic system capable of detecting papilledema from fundus photographs with high accuracy. By leveraging deep learning and image processing techniques, the proposed system will assist in rapid screening and triaging of patients, thereby reducing diagnostic delays and improving access to care. The system will be trained and validated on curated datasets of labeled fundus images, and designed for integration into low-cost hardware to ensure accessibility in underserved regions. This project holds the potential to democratize ophthalmic diagnostics and support early intervention for conditions associated with increased intracranial pressure. | L6: To develop a deep learning model capable of detecting papilledema from fundus images, enabling early diagnosis and timely referral of patients at risk of increased intracranial pressure. | M6: No
A7: 13 | B7: 45789.987 | C7: 45789.992 | D7: anonymous | G7: Mai Mabrouk | H7: masaid@nu.edu.eg | I7: Leveraging Multimodal Data Integration for Early Detection and Personalized Treatment in Fibrolamellar Carcinoma (FLC) | J7: Medical Informatics | K7: Fibrolamellar Carcinoma (FLC) is a rare form of primary liver cancer that primarily affects adolescents and young adults without underlying liver disease. Its elusive clinical presentation, scarcity of cases, and lack of standardized biomarkers contribute to delayed diagnosis and limited therapeutic guidance. This proposal aims to leverage the integration of multimodal data—including clinical parameters, radiological imaging (radiomics), and genomic profiles—to improve early detection and enable precision-guided treatment strategies for FLC.By employing advanced machine learning and deep learning frameworks, we will analyze feature-rich datasets extracted from multimodal sources to identify patterns and correlations that are not apparent through conventional analysis. | L7: The ultimate goal is to discover multimodal biomarkers that enhance diagnostic accuracy, stratify risk, and guide individualized therapy. This integrative approach holds the potential to transform clinical practice in FLC management and establish a framework applicable to other rare cancers. | M7: No
A8: 14 | B8: 45789.993 | C8: 45790 | D8: anonymous | G8: Mai Mabrouk | H8: masaid@nu.edu.eg | I8: Advancing Mental Health Assessment and Intervention through Multimodal Large Language Models | J8: Medical Informatics | K8: Mental health disorders remain a growing global concern, often underdiagnosed due to stigma, lack of resources, and the complexity of human psychological expression. Recent breakthroughs in artificial intelligence, particularly Large Language Models (LLMs), present a transformative opportunity for mental health care. This proposal explores the integration of multimodal data including textual conversations, voice tone, facial expressions, and physiological signals within advanced LLM frameworks to improve mental health assessment and intervention. By combining natural language understanding with audio and visual cues, multimodal LLMs can capture subtle indicators of emotional and cognitive states, offering deeper, context-aware insights into patient well-being. Leveraging datasets such as DAIC-WOZ, CMU Multimodal Opinion Sentiment and Emotion Intensity (CMU-MOSEI), and AVEC, the project aims to develop and validate models capable of early detection of conditions like depression, anxiety, and PTSD. Furthermore, the proposal envisions personalized, empathetic feedback mechanisms that support remote therapy and continuous mental health monitoring. This interdisciplinary approach promises to enhance clinical decision-making, improve patient engagement, and address gaps in mental health services, especially in underserved populations. | L8: The aims to develop a multimodal Large Language Model (LLM) framework that integrates text, audio, facial expressions, and physiological signals to improve the accuracy of mental health assessment and enable personalized, AI-driven interventions. | M8: No
A9: 15 | B9: 45790.001 | C9: 45790.004 | D9: anonymous | G9: Mai Mabrouk | H9: masaid@nu.edu.eg | I9: Artificial Intelligence-Guided Design of mRNA Vaccine Components: From Antigen Selection to Delivery Systems | J9: Bioinformatics | K9: The proposed topic focuses on utilizing artificial intelligence (AI) to revolutionize the development of mRNA vaccines by guiding critical stages from antigen selection to delivery system design. Through the integration of multi-omics data, protein structure prediction, and advanced machine learning techniques, the approach aims to identify the most effective and immunogenic antigens, optimize mRNA stability and translation, and design targeted delivery systems. This AI-driven framework has the potential to significantly accelerate vaccine development, enhance immune responses, and enable rapid adaptation to emerging infectious diseases. | L9: The aim is to harness artificial intelligence to streamline the end-to-end design of mRNA vaccine components, including optimal antigen selection, codon optimization, and delivery system engineering. By integrating multi-omics data, structural biology, and predictive machine learning models, the project seeks to accelerate the identification of potent immunogenic targets and enhance delivery efficiency, ultimately improving vaccine efficacy and development timelines. | M9: No
A10: 16 | B10: 45790.025 | C10: 45790.027 | D10: anonymous | G10: Mai Mabrouk | H10: masaid@nu.edu.eg | I10: AI-Based System for Early Detection, Classification, and Recurrence Prediction of Kidney Stones Using Imaging and Clinical Data | J10: Medical Informatics | K10: This project proposes the development of an AI-powered diagnostic and predictive system that utilizes medical imaging (e.g., CT, ultrasound) and patient clinical records to detect kidney stones, classify their type, and predict the likelihood of recurrence. The system will employ deep learning models such as convolutional neural networks (CNNs) for image analysis, combined with machine learning algorithms that integrate patient history, lab results, hydration levels, and metabolic profiles. This integrated tool aims to assist clinicians in early diagnosis, provide personalized treatment plans, and support long-term monitoring to prevent future occurrences. | L10: To create an integrated AI model that: Detects kidney stones from imaging data using deep learning. Classifies the type of kidney stone based on visual and clinical features. Predicts the risk of recurrence using longitudinal clinical data. | M10: No
A11: 17 | B11: 45790.029 | C11: 45790.045 | D11: anonymous | G11: Mai Mabrouk | H11: masaid@nu.edu.eg | I11: Digital Twin of the Lung: A Predictive Platform for Early Detection and Personalized Management of Respiratory Diseases | J11: Medical Informatics | K11: This project aims to develop a Digital Twin of the human lung—a dynamic, virtual physiological model that mirrors an individual’s lung function in real time using clinical, imaging, lifestyle, and omics data. The system will simulate respiratory behavior, track disease progression, and forecast health outcomes for conditions such as Chronic Obstructive Pulmonary Disease (COPD), asthma, and interstitial lung disease (ILD). | L11: Develop a virtual physiological lung model that integrates clinical, imaging, lifestyle, and omics data to simulate lung function, track respiratory health, and predict disease progression or response to treatment. | M11: No
A12: 18 | B12: 45790.628 | C12: 45790.629 | D12: anonymous | G12: Ensaf H. Mohamed | H12: enmohamed@nu.edu.eg | I12: EEG-Based Emotion and Sentiment Detection to Monitor Student Engagement | J12: Natural language processing | K12: This project uses EEG signals to detect students’ emotional states and levels of engagement during learning sessions. Brainwave data is collected and processed to identify sentiment and attention levels. | L12: To develop a real-time system that classifies student engagement and emotions using EEG and machine learning, enhancing adaptive learning environments. | M12: No
A13: 19 | B13: 45794.488 | C13: 45794.491 | D13: anonymous | G13: Mohamed Mysara and Ghada Ghoriba | H13: mmaysara@nu.edu.eg; GhadaKhoriba@nu.edu.eg | I13: Hypothesis testing preformance through LLM Models | J13: Bioinformatics | K13: developing of large language models (LLMs) tailored to automating formulation, statistical hypothesis testing, Interpretation directly from structured data without manual statistical coding. | L13: Developing end-to-end hypothesis testing workflows, significantly reducing the barrier to data-driven decision-making for non-experts. | M13: No
... A23: 29 | B23: 45796.483 | C23: 45796.485 | D23: anonymous | G23: Tamer Arafa | H23: tarafa@nu.edu.eg | I23: AutoClean: An LLM-Driven Autonomous Data Cleaning Assistant | J23: Natural language processing | K23: AutoClean is an intelligent data cleaning assistant that leverages large language models to automatically detect, explain, and correct data quality issues in tabular datasets. Combining LLM-based contextual reasoning with statistical anomaly detection, the system suggests cleaning actions such as imputations, outlier handling, and consistency fixes. Through an interactive interface, users can review and provide feedback on these suggestions, allowing the assistant to learn and improve its accuracy over time. AutoClean aims to reduce the manual effort and expertise needed for data preparation, accelerating data science workflows across industries. | L23: To develop an autonomous data cleaning system that: Identifies data inconsistencies, missing values, and anomalies using combined statistical and LLM reasoning, Generates natural language explanations and actionable cleaning suggestions, Incorporates user feedback to continuously improve through learning mechanisms, Integrates seamlessly with common data science environments for practical use. | M23: No
A24: 30 | B24: 45799.637 | C24: 45799.64 | D24: anonymous | G24: Sahar Selim; Mohamed Maysara | H24: sselim@nu.edu.eg; mmaysara@nu.edu.eg | I24: Automated Medical Coding of Breast Cancer Cases Using Machine Learning: A Collaboration Between Baheya Foundation and Nile University | J24: Medical Informatics | K24: Baheya Foundation currently manages a large clinical database of over 18,000 breast cancer cases, each with extensive medical documentation, including pathology reports and progress notes. Currently, the process of coding patient data using ICD-11 and ICD-O standards is handled by an external medical coding company. This process is resource-intensive, time-consuming, and not scalable. | L24: To develop an AI-based system capable of automatically extracting relevant diagnostic and procedural codes (ICD-11, ICD-O) from unstructured clinical text (e.g., pathology reports, progress notes), replacing the manual work of coding specialists. 1. Collect and anonymize a large set of annotated patient records from Baheya (with current manual codes). 2. Preprocess the text data, including cleaning, tokenization, and normalization. 3. Develop a supervised machine learning model (e.g., NLP-based deep learning or transformer model) trained on manually coded data. 4. Validate and evaluate the performance of the model against a held-out test set. 5. Create a user-friendly interface for hospital staff to upload reports and receive auto-generated ICD codes. | M24: No | N24: We need at least 2 BMD students in this project
A25: 31 | B25: 45799.64 | C25: 45799.642 | D25: anonymous | G25: Sahar Selim; Mohamed Maysara | H25: sselim@nu.edu.eg; mmaysara@nu.edu.eg | I25: SEER-Based Structured Data Extraction and Real-Time Cancer Registry Dashboard for Baheya | J25: Medical Informatics | K25: Problem Statement At Baheya Foundation, a large volume of unstructured data (e.g., pathology reports, radiology findings, clinical assessments, and progress notes) is generated daily. The current process of manually extracting and structuring these data according to SEER coding guidelines (for staging, diagnosis, treatment, etc.) is time-consuming, labor-intensive, and prone to delays. Moreover, the center lacks a live dashboard to provide real-time statistics for decision-making and research. Project Aim To develop an AI-powered platform that extracts structured SEER-compliant data from unstructured clinical documents and populates a live, queryable cancer registry database with built-in visualization tools. | L25: 1. Automated Data Extraction o Use Natural Language Processing (NLP) models to extract staging, morphology, topography, laterality, treatment, etc., from unstructured text in:  Pathology reports  Radiology reports  Initial assessments  Progress notes 2. SEER-Compliant Structuring o Map extracted information into structured fields following SEER Program standards (Site Recode ICD-O-3, Summary Stage 2018, etc.). 3. Live Database Design o Develop a secure, scalable relational database (e.g., PostgreSQL or MongoDB) with standardized fields. 4. Interactive Dashboard & Analytics o Build a user interface (web-based dashboard) that allows:  Real-time patient stats (e.g., stage distribution, subtypes, response to therapy)  Filters by year, stage, receptor status, age, etc.  Export-ready summaries for research and reports | M25: No | N25: We need at least 2 BMD students for this project
A26: 32 | B26: 45803.576 | C26: 45803.598 | D26: anonymous | G26: Sahar Ali Fawzi | H26: sfawzeia@nu.edu.eg | I26: Al-Assisted Prognosis Prediction. | J26: Medical Informatics | K26: This project explores the use of Artificial Intelligence (AI) to predict patient outcomes such as disease progression, survival time, and readmission risk. By training machine learning models on data from electronic health records (EHRs), lab results, and demographic profiles, the system aims to support clinicians in making data-driven prognosis decisions. The project compares different AI models for accuracy and clinical relevance, with a focus on interpretability, and patient safety. | L26: Create a predictive framework to predict patient outcomes such as disease progression, survival time, and readmission risk, thu enhances personalized care and improves medical decision-making | M26: No
A27: 33 | B27: 45803.598 | C27: 45803.601 | D27: anonymous | G27: Sahar Ali Fawzi | H27: sfawzi@nu.edu.eg | I27: AI-Guided Resource Allocation Optimization in Healthcare | J27: Medical Informatics | K27: To develop an AI-based decision support system to optimize resource allocation in healthcare environments. It uses predictive analytics and optimization algorithms to manage critical resources such as hospital beds, medical staff, and equipment. By analyzing historical and real-time data, the system identifies usage patterns and forecasts demand. The solution is tested using simulated healthcare data to evaluate its efficiency, fairness, and adaptability in dynamic scenarios. | L27: Improve healthcare delivery, with affordable budjets. by enabling smarter, data-driven resource management. | M27: No
A28: 34 | B28: 45803.601 | C28: 45803.607 | D28: anonymous | G28: Sahar Ali Fawzi | H28: sfawzi@nu.edu.eg | I28: AI-Guided Treatment Planning & Recommendation | J28: Medical Informatics | K28: This project presents a machine learning-based system designed to assist healthcare professionals in developing personalized treatment plans. By analyzing clinical data such as diagnoses, lab results, comorbidities, and medical history, the system recommends treatment strategies aligned with current medical standards. The solution supports evidence-based decision-making, reduces the risk of errors, and promotes individualized care. The project also addresses important concerns related to model transparency, safety, and clinical integration, aiming to create a reliable AI assistant for treatment planning. | L28: develop a platform to achieve precision medicine | M28: No
A29: 35 | B29: 45803.608 | C29: 45803.61 | D29: anonymous | G29: Sahar Ali Fawzi | H29: sfawzi@nu.edu.eg | I29: Generative AI (LLMs) Guided Text and Speech Recognition in EMR | J29: Medical Informatics | K29: This project focuses on enhancing Electronic Medical Record (EMR) systems through generative AI, particularly Large Language Models (LLMs). The goal is to improve the recognition and structuring of both spoken and written clinical data. The system performs real-time speech-to-text transcription, summarizes clinical notes, and organizes unstructured inputs into standardized EMR formats. By reducing documentation time and improving accuracy, this approach allows healthcare providers to spend more time with patients. The project also considers privacy, security, and the practical challenges of deploying AI in clinical settings | L29: Use of more natural way to deal with EHR | M29: No
A30: 36 | B30: 45803.61 | C30: 45803.612 | D30: anonymous | G30: Sahar Ali Fawzi | H30: sfawzi@nu.edu.eg | I30: Generative AI Augmented Electronic Medical Records (EMR) | J30: Medical Informatics | K30: Leveraging Large Language Models (LLMs), the system performs automated tasks such as summarizing patient histories, generating clinical notes, and recommending actions based on context. The objective is to reduce the burden of manual data entry while improving data quality and usability. A prototype should be developed and evaluated using clinical data to test performance, compliance with standards, and user-friendliness. The project envisions a future where EMRs actively assist clinicians in decision-making and patient management. | L30: A generative AI-enhanced framework for transforming EMR systems into intelligent, interactive platforms. | M30: No
A31: 38 | B31: 45812.426 | C31: 45812.457 | D31: anonymous | G31: Mai Mabrouk | H31: Mabrouk | I31: AI-Enhanced Surgical Navigation System using Augmented Reality” | J31: Medical Imaging and Image Processing | K31: Conventional surgical procedures often depend on the surgeon’s experience, 2D preoperative images, and limited intraoperative feedback, which can increase the risk of complications. There is a need for a system that enhances spatial awareness and anatomical visualization during surgery. | L31: To develop an AI-assisted augmented reality (AR) surgical navigation system that provides real-time, accurate visualization and guidance during surgeries, aiming to increase precision, reduce errors, and improve patient outcomes. | M31: No
A32: 65 | B32: 45839.659 | C32: 45839.663 | D32: anonymous | G32: Walaa Medhat | H32: WMedhat@nu.edu.eg | I32: Emotion-Aware Chatbot Using Multi-Task Learning | J32: Natural language processing | L32: This project aims to build an intelligent chatbot capable of understanding both the semantic content and the emotional tone of user inputs. Using multi-task learning, the model will simultaneously perform sentiment analysis and intent classification to generate context- and emotion-aware responses. The system will be trained on multi-label conversational datasets and benchmarked against standard chatbots for empathy and engagement, offering potential use in mental health support or customer service. | M32: No
A33: 66 | B33: 45839.663 | C33: 45839.664 | D33: anonymous | G33: Walaa Medhat | H33: WMedhat@nu.edu.eg | I33: Multilingual Fake News Detection Using Cross-Lingual Embeddings | J33: Natural language processing | L33: Misinformation is a global issue that transcends language barriers. This project aims to propose a multilingual fake news detection system that leverages cross-lingual embeddings (e.g., XLM-RoBERTa) to detect fake news across different languages. The model will be trained on multilingual datasets and evaluated for accuracy, precision, and generalizability. This system could be especially useful for global media platforms or international organizations combating disinformation. | M33: No
A34: 67 | B34: 45839.665 | C34: 45839.666 | D34: anonymous | G34: Walaa Medhat | H34: WMedhat@nu.edu.eg | I34: Automated Code Review Assistant Using Static Analysis and Machine Learning | J34: Software and Systems | L34: Code review is a critical step in the software development lifecycle but is often time-consuming and inconsistent. This project proposes an intelligent code review assistant that integrates static code analysis tools (e.g., SonarQube) with machine learning models trained on historical code review data. The system will automatically detect common bugs, code smells, and violations of coding standards, and suggest improvements based on prior reviews. The goal is to enhance code quality and reduce manual review efforts, particularly for large-scale or distributed development teams. | M34: No
A35: 68 | B35: 45839.667 | C35: 45839.667 | D35: anonymous | G35: Walaa Medhat | H35: WMedhat@nu.edu.eg | I35: Automated Testing Suite for RESTful APIs | J35: Software and Systems | L35: Testing REST APIs is essential to ensure backend reliability and consistency. This project involves building an automated testing tool that reads OpenAPI (Swagger) specifications to generate and run test cases for API endpoints. The tool will test for functionality, edge cases, and security vulnerabilities (e.g., SQL injection, broken authentication). It will include a web-based dashboard to show test coverage, response time, and success rates, supporting CI/CD integration. | M35: No

Sheet Sheet3
A1: # | B1: Student ID | C1: Program | D1: Student Name | E1: Email Address | F1: GPA after Fall 24 | G1: Estimated earned Credits after Spring 25 | H1: GPA after Spring 25 | I1: Accual earned Credits after Spring 25 | J1: Assigned
A2: 1 | B2: 221001554 | C2: AI | D2: Saif Eldin Mohamed Rady | E2: S.Mohamed2254@nu.edu.eg | F2: 3.47 | G2: 110 | H2: 3.39 | I2: 110 | J2: =VLOOKUP(B2,'ALL Projects'!$A$2:$C470,2,0) -> #N/A
A3: 2 | B3: 221000043 | C3: AI | D3: Ahmed Amin Amin | E3: A.Amin2243@nu.edu.eg | F3: 2.44 | G3: 109 | H3: 2.37 | I3: 104 | J3: =VLOOKUP(B3,'ALL Projects'!$A$2:$C471,2,0) -> #N/A
A4: 3 | B4: 221000432 | C4: AI | D4: Mustafa Mohamed Zakaria AbdelSalam Ahmed Sultan | E4: M.Mohamed2232@nu.edu.eg | F4: 3.86 | G4: 108 | H4: 3.83 | I4: 108 | J4: =VLOOKUP(B4,'ALL Projects'!$A$2:$C472,2,0) -> #N/A
A5: 4 | B5: 202000963 | C5: AI | D5: Zeyad Mohsen Elkahwagi | E5: Z.Mohsen@nu.edu.eg | F5: 1.81 | G5: 105 | H5: 1.76 | I5: 93 | J5: =VLOOKUP(B5,'ALL Projects'!$A$2:$C473,2,0) -> #N/A
A6: 5 | B6: 221000424 | C6: AI | D6: Doaa Mahdy Agha | E6: D.Mahdy2224@nu.edu.eg | F6: 3.86 | G6: 105 | H6: 3.87 | I6: 105 | J6: =VLOOKUP(B6,'ALL Projects'!$A$2:$C478,2,0) -> #N/A
A7: 6 | B7: 221000410 | C7: AI | D7: Jana Ayman Ahmed Radwan | E7: J.Ayman2210@nu.edu.eg | F7: 3.87 | G7: 104 | H7: 3.86 | I7: 104 | J7: =VLOOKUP(B7,'ALL Projects'!$A$2:$C570,2,0) -> #N/A
A8: 7 | B8: 221000828 | C8: AI | D8: Karim raouf mostafa | E8: k.raouf2228@nu.edu.eg | F8: 3.62 | G8: 104 | H8: 3.67 | I8: 104 | J8: =VLOOKUP(B8,'ALL Projects'!$A$2:$C570,2,0) -> #N/A
A9: 8 | B9: 221001792 | C9: AI | D9: Amenah Medhat Moselhy | E9: a.Medhat2292@nu.edu.eg | F9: 3.93 | G9: 104 | H9: 3.94 | I9: 104 | J9: =VLOOKUP(B9,'ALL Projects'!$A$2:$C480,2,0) -> #N/A
A10: 9 | B10: 221002051 | C10: AI | D10: Seif Usama kassab | E10: s.Usama2251@nu.edu.eg | F10: 3.72 | G10: 104 | H10: 3.72 | I10: 104 | J10: =VLOOKUP(B10,'ALL Projects'!$A$2:$C476,2,0) -> #N/A
A11: 10 | B11: 211001298 | C11: AI | D11: Mohamed Ibrahim Salama | E11: M.Ibrahim2198@nu.edu.eg | F11: 2.36 | G11: 103 | H11: 2.48 | I11: 101 | J11: =VLOOKUP(B11,'ALL Projects'!$A$2:$C478,2,0) -> #N/A
A12: 11 | B12: 221000123 | C12: AI | D12: Farida Sheref Salah | E12: F.Sheref2223@nu.edu.eg | F12: 2.92 | G12: 103 | H12: 2.89 | I12: 103 | J12: =VLOOKUP(B12,'ALL Projects'!$A$2:$C480,2,0) -> #N/A
A13: 12 | B13: 221000142 | C13: AI | D13: Mohamed Sherif Hassan El sayd Elian sherif Elian | E13: M.sherif2242@nu.edu.eg | F13: 3.35 | G13: 102 | H13: 3.28 | I13: 102 | J13: =VLOOKUP(B13,'ALL Projects'!$A$2:$C481,2,0) -> #N/A
A14: 13 | B14: 221000347 | C14: AI | D14: KARIM MOHAMED ABDALLA | E14: K.MOHAMED2247@nu.edu.eg | F14: 2.9 | G14: 102 | H14: 2.94 | I14: 102 | J14: =VLOOKUP(B14,'ALL Projects'!$A$2:$C482,2,0) -> #N/A
A15: 14 | B15: 221000645 | C15: AI | D15: Shorouk Sherif Elbehairy | E15: S.Sherif2245@nu.edu.eg | F15: 3.95 | G15: 102 | H15: 3.96 | I15: 102 | J15: =VLOOKUP(B15,'ALL Projects'!$A$2:$C483,2,0) -> #N/A
A16: 15 | B16: 221000759 | C16: AI | D16: Ranim Hisham Niazy | E16: R.Hisham2259@nu.edu.eg | F16: 3.62 | G16: 102 | H16: 3.67 | I16: 102 | J16: =VLOOKUP(B16,'ALL Projects'!$A$2:$C484,2,0) -> #N/A
A17: 16 | B17: 221000770 | C17: AI | D17: Hossam Nasr Mohamed | E17: H.Nasr2270@nu.edu.eg | F17: 4 | G17: 102 | H17: 4 | I17: 102 | J17: =VLOOKUP(B17,'ALL Projects'!$A$2:$C485,2,0) -> #N/A
A18: 17 | B18: 221000832 | C18: AI | D18: Amr Hossam Gamal | E18: A.Hossam2232@nu.edu.eg | F18: 4 | G18: 102 | H18: 4 | I18: 102 | J18: =VLOOKUP(B18,'ALL Projects'!$A$2:$C486,2,0) -> #N/A
A19: 18 | B19: 221001099 | C19: AI | D19: Ahmed Hazem Hassan | E19: A.Hazem2299@nu.edu.eg | F19: 4 | G19: 102 | H19: 4 | I19: 102 | J19: =VLOOKUP(B19,'ALL Projects'!$A$2:$C487,2,0) -> #N/A
A20: 19 | B20: 221001237 | C20: AI | D20: Farida Amr Farouk | E20: f.Amr2237@nu.edu.eg | F20: 3.63 | G20: 102 | H20: 3.68 | I20: 102 | J20: =VLOOKUP(B20,'ALL Projects'!$A$2:$C488,2,0) -> #N/A
A21: 20 | B21: 221001524 | C21: AI | D21: Ahmed Kamal Helmy | E21: A.Kamal2224@nu.edu.eg | F21: 3.14 | G21: 102 | H21: 3.15 | I21: 102 | J21: =VLOOKUP(B21,'ALL Projects'!$A$2:$C489,2,0) -> #N/A
A22: 21 | B22: 221001565 | C22: AI | D22: Mohamed Nashaat Ibrahim Hassan | E22: M.Nashaat2265@nu.edu.eg | F22: 3.53 | G22: 102 | H22: 3.53 | I22: 102 | J22: =VLOOKUP(B22,'ALL Projects'!$A$2:$C490,2,0) -> #N/A
A23: 22 | B23: 221001592 | C23: AI | D23: Farah mohamed ibrahem | E23: f.mohamed2292@nu.edu.eg | F23: 3.22 | G23: 102 | H23: 3.27 | I23: 102 | J23: =VLOOKUP(B23,'ALL Projects'!$A$2:$C491,2,0) -> #N/A
... A28: 27 | B28: 221001347 | C28: AI | D28: Omar Mohamed Radwan | E28: O.Mohamed2247@nu.edu.eg | F28: 3.84 | G28: 101 | H28: 3.81 | I28: 101 | J28: =VLOOKUP(B28,'ALL Projects'!$A$2:$C496,2,0) -> #N/A
A29: 28 | B29: 221001470 | C29: AI | D29: Khetam MOHAMED FARHAN almasrany | E29: k.MOHAMED2270@nu.edu.eg | F29: 3.8 | G29: 101 | H29: 3.78 | I29: 101 | J29: =VLOOKUP(B29,'ALL Projects'!$A$2:$C505,2,0) -> #N/A
A30: 29 | B30: 221001493 | C30: AI | D30: Nezar Emadeldin Abdelmonem koutb | E30: N.Emadeldin2293@nu.edu.eg | F30: 3.02 | G30: 101 | H30: 3.14 | I30: 101 | J30: =VLOOKUP(B30,'ALL Projects'!$A$2:$C505,2,0) -> #N/A
A31: 30 | B31: 221001646 | C31: AI | D31: Karim ayman salah elden | E31: k.ayman2246@nu.edu.eg | F31: 3.68 | G31: 101 | H31: 3.73 | I31: 101 | J31: =VLOOKUP(B31,'ALL Projects'!$A$2:$C505,2,0) -> #N/A
